Watching for file changes with StatReloader
Performing system checks...

Exception in thread django-main-thread:
Traceback (most recent call last):
  File "C:\Users\Brisen Whyte\AppData\Local\Programs\Python\Python36\lib\threading.py", line 916, in _bootstrap_inner
    self.run()
  File "C:\Users\Brisen Whyte\AppData\Local\Programs\Python\Python36\lib\threading.py", line 864, in run
    self._target(*self._args, **self._kwargs)
  File "D:\PROJ2\venv\lib\site-packages\django\utils\autoreload.py", line 64, in wrapper
    fn(*args, **kwargs)
  File "D:\PROJ2\venv\lib\site-packages\django\core\management\commands\runserver.py", line 118, in inner_run
    self.check(display_num_errors=True)
  File "D:\PROJ2\venv\lib\site-packages\django\core\management\base.py", line 423, in check
    databases=databases,
  File "D:\PROJ2\venv\lib\site-packages\django\core\checks\registry.py", line 76, in run_checks
    new_errors = check(app_configs=app_configs, databases=databases)
  File "D:\PROJ2\venv\lib\site-packages\django\core\checks\urls.py", line 13, in check_url_config
    return check_resolver(resolver)
  File "D:\PROJ2\venv\lib\site-packages\django\core\checks\urls.py", line 23, in check_resolver
    return check_method()
  File "D:\PROJ2\venv\lib\site-packages\django\urls\resolvers.py", line 416, in check
    for pattern in self.url_patterns:
  File "D:\PROJ2\venv\lib\site-packages\django\utils\functional.py", line 48, in __get__
    res = instance.__dict__[self.name] = self.func(instance)
  File "D:\PROJ2\venv\lib\site-packages\django\urls\resolvers.py", line 602, in url_patterns
    patterns = getattr(self.urlconf_module, "urlpatterns", self.urlconf_module)
  File "D:\PROJ2\venv\lib\site-packages\django\utils\functional.py", line 48, in __get__
    res = instance.__dict__[self.name] = self.func(instance)
  File "D:\PROJ2\venv\lib\site-packages\django\urls\resolvers.py", line 595, in urlconf_module
    return import_module(self.urlconf_name)
  File "C:\Users\Brisen Whyte\AppData\Local\Programs\Python\Python36\lib\importlib\__init__.py", line 126, in import_module
    return _bootstrap._gcd_import(name[level:], package, level)
  File "<frozen importlib._bootstrap>", line 994, in _gcd_import
  File "<frozen importlib._bootstrap>", line 971, in _find_and_load
  File "<frozen importlib._bootstrap>", line 955, in _find_and_load_unlocked
  File "<frozen importlib._bootstrap>", line 665, in _load_unlocked
  File "<frozen importlib._bootstrap_external>", line 678, in exec_module
  File "<frozen importlib._bootstrap>", line 219, in _call_with_frames_removed
  File "D:\PROJ2\Deepfake\Django Application\project_settings\urls.py", line 10, in <module>
    path('', include('ml_app.urls')),
  File "D:\PROJ2\venv\lib\site-packages\django\urls\conf.py", line 34, in include
    urlconf_module = import_module(urlconf_module)
  File "C:\Users\Brisen Whyte\AppData\Local\Programs\Python\Python36\lib\importlib\__init__.py", line 126, in import_module
    return _bootstrap._gcd_import(name[level:], package, level)
  File "<frozen importlib._bootstrap>", line 994, in _gcd_import
  File "<frozen importlib._bootstrap>", line 971, in _find_and_load
  File "<frozen importlib._bootstrap>", line 955, in _find_and_load_unlocked
  File "<frozen importlib._bootstrap>", line 665, in _load_unlocked
  File "<frozen importlib._bootstrap_external>", line 678, in exec_module
  File "<frozen importlib._bootstrap>", line 219, in _call_with_frames_removed
  File "D:\PROJ2\Deepfake\Django Application\ml_app\urls.py", line 5, in <module>
    from . import views
  File "D:\PROJ2\Deepfake\Django Application\ml_app\views.py", line 215, in <module>
    from rest_framework.decorators import api_view
ModuleNotFoundError: No module named 'rest_framework'

^C